Traceback (most recent call last):
  File "D:\Users\Downloads\yolov7-main\utils\google_utils.py", line 26, in attempt_download
    assets = [x['name'] for x in response['assets']]  # release assets
KeyError: 'assets'
During handling of the above exception, another exception occurred:
Traceback (most recent call last):
  File "D:\Users\Downloads\yolov7-main\train.py", line 728, in <module>
    train(hyp, opt, device, tb_writer)
  File "D:\Users\Downloads\yolov7-main\train.py", line 97, in train
    attempt_download(weights)  # download if not found locally
  File "D:\Users\Downloads\yolov7-main\utils\google_utils.py", line 31, in attempt_download
    tag = subprocess.check_output('git tag', shell=True).decode().split()[-1]
  File "C:\Users\thanh\AppData\Local\Programs\Python\Python310\lib\subprocess.py", line 420, in check_output
    return run(*popenargs, stdout=PIPE, timeout=timeout, check=True,
  File "C:\Users\thanh\AppData\Local\Programs\Python\Python310\lib\subprocess.py", line 524, in run
    raise CalledProcessError(retcode, process.args,
subprocess.CalledProcessError: Command 'git tag' returned non-zero exit status 1.